[2022-03-14 15:29:06,790] {taskinstance.py:1037} INFO - Dependencies all met for <TaskInstance: main_dag.fetch_weather_data manual__2022-03-14T15:28:26.453474+00:00 [queued]>
[2022-03-14 15:29:06,839] {taskinstance.py:1037} INFO - Dependencies all met for <TaskInstance: main_dag.fetch_weather_data manual__2022-03-14T15:28:26.453474+00:00 [queued]>
[2022-03-14 15:29:06,841] {taskinstance.py:1243} INFO - 
--------------------------------------------------------------------------------
[2022-03-14 15:29:06,843] {taskinstance.py:1244} INFO - Starting attempt 2 of 2
[2022-03-14 15:29:06,845] {taskinstance.py:1245} INFO - 
--------------------------------------------------------------------------------
[2022-03-14 15:29:06,893] {taskinstance.py:1264} INFO - Executing <Task(PythonOperator): fetch_weather_data> on 2022-03-14 15:28:26.453474+00:00
[2022-03-14 15:29:06,903] {standard_task_runner.py:52} INFO - Started process 2307 to run task
[2022-03-14 15:29:06,913] {standard_task_runner.py:76} INFO - Running: ['***', 'tasks', 'run', 'main_dag', 'fetch_weather_data', 'manual__2022-03-14T15:28:26.453474+00:00', '--job-id', '4', '--raw', '--subdir', 'DAGS_FOLDER/main_dag.py', '--cfg-path', '/tmp/tmp210qfrsm', '--error-file', '/tmp/tmpyxhxbf3r']
[2022-03-14 15:29:06,916] {standard_task_runner.py:77} INFO - Job 4: Subtask fetch_weather_data
[2022-03-14 15:29:07,058] {logging_mixin.py:109} INFO - Running <TaskInstance: main_dag.fetch_weather_data manual__2022-03-14T15:28:26.453474+00:00 [running]> on host 0bb54ecb374d
[2022-03-14 15:29:07,193] {taskinstance.py:1431} INFO - Exporting the following env vars:
AIRFLOW_CTX_DAG_OWNER=***
AIRFLOW_CTX_DAG_ID=main_dag
AIRFLOW_CTX_TASK_ID=fetch_weather_data
AIRFLOW_CTX_EXECUTION_DATE=2022-03-14T15:28:26.453474+00:00
AIRFLOW_CTX_DAG_RUN_ID=manual__2022-03-14T15:28:26.453474+00:00
[2022-03-14 15:29:09,215] {logging_mixin.py:109} INFO - 2
[2022-03-14 15:29:09,217] {get_current_weather_data.py:46} ERROR - Request for Assam unsuccessful with status code: 429
[2022-03-14 15:29:09,219] {get_current_weather_data.py:47} INFO - JSON Response:
{"message":"You have exceeded the rate limit per minute for your plan, BASIC, by the API provider"}
[2022-03-14 15:29:09,250] {taskinstance.py:1718} ERROR - Task failed with exception
Traceback (most recent call last):
  File "/opt/airflow/dags/python_scripts/get_current_weather_data.py", line 43, in get_current_weather_data
    raise Exception
Exception

During handling of the above exception, another exception occurred:

Traceback (most recent call last):
  File "/home/airflow/.local/lib/python3.7/site-packages/airflow/models/taskinstance.py", line 1334, in _run_raw_task
    self._execute_task_with_callbacks(context)
  File "/home/airflow/.local/lib/python3.7/site-packages/airflow/models/taskinstance.py", line 1460, in _execute_task_with_callbacks
    result = self._execute_task(context, self.task)
  File "/home/airflow/.local/lib/python3.7/site-packages/airflow/models/taskinstance.py", line 1516, in _execute_task
    result = execute_callable(context=context)
  File "/home/airflow/.local/lib/python3.7/site-packages/airflow/operators/python.py", line 174, in execute
    return_value = self.execute_callable()
  File "/home/airflow/.local/lib/python3.7/site-packages/airflow/operators/python.py", line 188, in execute_callable
    return self.python_callable(*self.op_args, **self.op_kwargs)
  File "/opt/airflow/dags/python_scripts/get_current_weather_data.py", line 48, in get_current_weather_data
    raise AirflowException
airflow.exceptions.AirflowException
[2022-03-14 15:29:09,282] {taskinstance.py:1282} INFO - Marking task as FAILED. dag_id=main_dag, task_id=fetch_weather_data, execution_date=20220314T152826, start_date=20220314T152906, end_date=20220314T152909
[2022-03-14 15:29:09,324] {standard_task_runner.py:92} ERROR - Failed to execute job 4 for task fetch_weather_data
Traceback (most recent call last):
  File "/opt/airflow/dags/python_scripts/get_current_weather_data.py", line 43, in get_current_weather_data
    raise Exception
Exception

During handling of the above exception, another exception occurred:

Traceback (most recent call last):
  File "/home/airflow/.local/lib/python3.7/site-packages/airflow/task/task_runner/standard_task_runner.py", line 85, in _start_by_fork
    args.func(args, dag=self.dag)
  File "/home/airflow/.local/lib/python3.7/site-packages/airflow/cli/cli_parser.py", line 48, in command
    return func(*args, **kwargs)
  File "/home/airflow/.local/lib/python3.7/site-packages/airflow/utils/cli.py", line 92, in wrapper
    return f(*args, **kwargs)
  File "/home/airflow/.local/lib/python3.7/site-packages/airflow/cli/commands/task_command.py", line 298, in task_run
    _run_task_by_selected_method(args, dag, ti)
  File "/home/airflow/.local/lib/python3.7/site-packages/airflow/cli/commands/task_command.py", line 107, in _run_task_by_selected_method
    _run_raw_task(args, ti)
  File "/home/airflow/.local/lib/python3.7/site-packages/airflow/cli/commands/task_command.py", line 184, in _run_raw_task
    error_file=args.error_file,
  File "/home/airflow/.local/lib/python3.7/site-packages/airflow/utils/session.py", line 70, in wrapper
    return func(*args, session=session, **kwargs)
  File "/home/airflow/.local/lib/python3.7/site-packages/airflow/models/taskinstance.py", line 1334, in _run_raw_task
    self._execute_task_with_callbacks(context)
  File "/home/airflow/.local/lib/python3.7/site-packages/airflow/models/taskinstance.py", line 1460, in _execute_task_with_callbacks
    result = self._execute_task(context, self.task)
  File "/home/airflow/.local/lib/python3.7/site-packages/airflow/models/taskinstance.py", line 1516, in _execute_task
    result = execute_callable(context=context)
  File "/home/airflow/.local/lib/python3.7/site-packages/airflow/operators/python.py", line 174, in execute
    return_value = self.execute_callable()
  File "/home/airflow/.local/lib/python3.7/site-packages/airflow/operators/python.py", line 188, in execute_callable
    return self.python_callable(*self.op_args, **self.op_kwargs)
  File "/opt/airflow/dags/python_scripts/get_current_weather_data.py", line 48, in get_current_weather_data
    raise AirflowException
airflow.exceptions.AirflowException
[2022-03-14 15:29:09,357] {local_task_job.py:154} INFO - Task exited with return code 1
[2022-03-14 15:29:09,481] {local_task_job.py:264} INFO - 0 downstream tasks scheduled from follow-on schedule check
