[2022-03-14 13:09:38,923] {taskinstance.py:1037} INFO - Dependencies all met for <TaskInstance: main_dag.populate_weather_table manual__2022-03-14T13:09:01.255422+00:00 [queued]>
[2022-03-14 13:09:38,960] {taskinstance.py:1037} INFO - Dependencies all met for <TaskInstance: main_dag.populate_weather_table manual__2022-03-14T13:09:01.255422+00:00 [queued]>
[2022-03-14 13:09:38,962] {taskinstance.py:1243} INFO - 
--------------------------------------------------------------------------------
[2022-03-14 13:09:38,963] {taskinstance.py:1244} INFO - Starting attempt 2 of 2
[2022-03-14 13:09:38,965] {taskinstance.py:1245} INFO - 
--------------------------------------------------------------------------------
[2022-03-14 13:09:39,008] {taskinstance.py:1264} INFO - Executing <Task(PostgresOperator): populate_weather_table> on 2022-03-14 13:09:01.255422+00:00
[2022-03-14 13:09:39,016] {standard_task_runner.py:52} INFO - Started process 400 to run task
[2022-03-14 13:09:39,023] {standard_task_runner.py:76} INFO - Running: ['***', 'tasks', 'run', 'main_dag', 'populate_weather_table', 'manual__2022-03-14T13:09:01.255422+00:00', '--job-id', '8', '--raw', '--subdir', 'DAGS_FOLDER/main_dag.py', '--cfg-path', '/tmp/tmp_94g77s0', '--error-file', '/tmp/tmpxiautn9z']
[2022-03-14 13:09:39,026] {standard_task_runner.py:77} INFO - Job 8: Subtask populate_weather_table
[2022-03-14 13:09:39,161] {logging_mixin.py:109} INFO - Running <TaskInstance: main_dag.populate_weather_table manual__2022-03-14T13:09:01.255422+00:00 [running]> on host e0810cf0708b
[2022-03-14 13:09:39,307] {taskinstance.py:1431} INFO - Exporting the following env vars:
AIRFLOW_CTX_DAG_OWNER=***
AIRFLOW_CTX_DAG_ID=main_dag
AIRFLOW_CTX_TASK_ID=populate_weather_table
AIRFLOW_CTX_EXECUTION_DATE=2022-03-14T13:09:01.255422+00:00
AIRFLOW_CTX_DAG_RUN_ID=manual__2022-03-14T13:09:01.255422+00:00
[2022-03-14 13:09:39,359] {taskinstance.py:1718} ERROR - Task failed with exception
Traceback (most recent call last):
  File "/home/airflow/.local/lib/python3.7/site-packages/airflow/models/taskinstance.py", line 1334, in _run_raw_task
    self._execute_task_with_callbacks(context)
  File "/home/airflow/.local/lib/python3.7/site-packages/airflow/models/taskinstance.py", line 1460, in _execute_task_with_callbacks
    result = self._execute_task(context, self.task)
  File "/home/airflow/.local/lib/python3.7/site-packages/airflow/models/taskinstance.py", line 1516, in _execute_task
    result = execute_callable(context=context)
  File "/home/airflow/.local/lib/python3.7/site-packages/airflow/providers/postgres/operators/postgres.py", line 71, in execute
    self.hook.run(self.sql, self.autocommit, parameters=self.parameters)
  File "/home/airflow/.local/lib/python3.7/site-packages/airflow/hooks/dbapi.py", line 198, in run
    with closing(self.get_conn()) as conn:
  File "/home/airflow/.local/lib/python3.7/site-packages/airflow/providers/postgres/hooks/postgres.py", line 86, in get_conn
    conn = deepcopy(self.connection or self.get_connection(conn_id))
  File "/home/airflow/.local/lib/python3.7/site-packages/airflow/hooks/base.py", line 68, in get_connection
    conn = Connection.get_connection_from_secrets(conn_id)
  File "/home/airflow/.local/lib/python3.7/site-packages/airflow/models/connection.py", line 410, in get_connection_from_secrets
    raise AirflowNotFoundException(f"The conn_id `{conn_id}` isn't defined")
airflow.exceptions.AirflowNotFoundException: The conn_id `postgres_default` isn't defined
[2022-03-14 13:09:39,392] {taskinstance.py:1282} INFO - Marking task as FAILED. dag_id=main_dag, task_id=populate_weather_table, execution_date=20220314T130901, start_date=20220314T130938, end_date=20220314T130939
[2022-03-14 13:09:39,435] {standard_task_runner.py:92} ERROR - Failed to execute job 8 for task populate_weather_table
Traceback (most recent call last):
  File "/home/airflow/.local/lib/python3.7/site-packages/airflow/task/task_runner/standard_task_runner.py", line 85, in _start_by_fork
    args.func(args, dag=self.dag)
  File "/home/airflow/.local/lib/python3.7/site-packages/airflow/cli/cli_parser.py", line 48, in command
    return func(*args, **kwargs)
  File "/home/airflow/.local/lib/python3.7/site-packages/airflow/utils/cli.py", line 92, in wrapper
    return f(*args, **kwargs)
  File "/home/airflow/.local/lib/python3.7/site-packages/airflow/cli/commands/task_command.py", line 298, in task_run
    _run_task_by_selected_method(args, dag, ti)
  File "/home/airflow/.local/lib/python3.7/site-packages/airflow/cli/commands/task_command.py", line 107, in _run_task_by_selected_method
    _run_raw_task(args, ti)
  File "/home/airflow/.local/lib/python3.7/site-packages/airflow/cli/commands/task_command.py", line 184, in _run_raw_task
    error_file=args.error_file,
  File "/home/airflow/.local/lib/python3.7/site-packages/airflow/utils/session.py", line 70, in wrapper
    return func(*args, session=session, **kwargs)
  File "/home/airflow/.local/lib/python3.7/site-packages/airflow/models/taskinstance.py", line 1334, in _run_raw_task
    self._execute_task_with_callbacks(context)
  File "/home/airflow/.local/lib/python3.7/site-packages/airflow/models/taskinstance.py", line 1460, in _execute_task_with_callbacks
    result = self._execute_task(context, self.task)
  File "/home/airflow/.local/lib/python3.7/site-packages/airflow/models/taskinstance.py", line 1516, in _execute_task
    result = execute_callable(context=context)
  File "/home/airflow/.local/lib/python3.7/site-packages/airflow/providers/postgres/operators/postgres.py", line 71, in execute
    self.hook.run(self.sql, self.autocommit, parameters=self.parameters)
  File "/home/airflow/.local/lib/python3.7/site-packages/airflow/hooks/dbapi.py", line 198, in run
    with closing(self.get_conn()) as conn:
  File "/home/airflow/.local/lib/python3.7/site-packages/airflow/providers/postgres/hooks/postgres.py", line 86, in get_conn
    conn = deepcopy(self.connection or self.get_connection(conn_id))
  File "/home/airflow/.local/lib/python3.7/site-packages/airflow/hooks/base.py", line 68, in get_connection
    conn = Connection.get_connection_from_secrets(conn_id)
  File "/home/airflow/.local/lib/python3.7/site-packages/airflow/models/connection.py", line 410, in get_connection_from_secrets
    raise AirflowNotFoundException(f"The conn_id `{conn_id}` isn't defined")
airflow.exceptions.AirflowNotFoundException: The conn_id `postgres_default` isn't defined
[2022-03-14 13:09:39,482] {local_task_job.py:154} INFO - Task exited with return code 1
[2022-03-14 13:09:39,559] {local_task_job.py:264} INFO - 0 downstream tasks scheduled from follow-on schedule check
