[2022-03-14 15:34:28,932] {taskinstance.py:1037} INFO - Dependencies all met for <TaskInstance: main_dag.create_weather_table manual__2022-03-14T15:34:16.519518+00:00 [queued]>
[2022-03-14 15:34:28,970] {taskinstance.py:1037} INFO - Dependencies all met for <TaskInstance: main_dag.create_weather_table manual__2022-03-14T15:34:16.519518+00:00 [queued]>
[2022-03-14 15:34:28,971] {taskinstance.py:1243} INFO - 
--------------------------------------------------------------------------------
[2022-03-14 15:34:28,972] {taskinstance.py:1244} INFO - Starting attempt 1 of 2
[2022-03-14 15:34:28,974] {taskinstance.py:1245} INFO - 
--------------------------------------------------------------------------------
[2022-03-14 15:34:29,014] {taskinstance.py:1264} INFO - Executing <Task(PostgresOperator): create_weather_table> on 2022-03-14 15:34:16.519518+00:00
[2022-03-14 15:34:29,022] {standard_task_runner.py:52} INFO - Started process 2754 to run task
[2022-03-14 15:34:29,029] {standard_task_runner.py:76} INFO - Running: ['***', 'tasks', 'run', 'main_dag', 'create_weather_table', 'manual__2022-03-14T15:34:16.519518+00:00', '--job-id', '7', '--raw', '--subdir', 'DAGS_FOLDER/main_dag.py', '--cfg-path', '/tmp/tmp8zu5qhmw', '--error-file', '/tmp/tmpesjjw090']
[2022-03-14 15:34:29,032] {standard_task_runner.py:77} INFO - Job 7: Subtask create_weather_table
[2022-03-14 15:34:29,144] {logging_mixin.py:109} INFO - Running <TaskInstance: main_dag.create_weather_table manual__2022-03-14T15:34:16.519518+00:00 [running]> on host 0bb54ecb374d
[2022-03-14 15:34:29,272] {taskinstance.py:1431} INFO - Exporting the following env vars:
AIRFLOW_CTX_DAG_OWNER=***
AIRFLOW_CTX_DAG_ID=main_dag
AIRFLOW_CTX_TASK_ID=create_weather_table
AIRFLOW_CTX_EXECUTION_DATE=2022-03-14T15:34:16.519518+00:00
AIRFLOW_CTX_DAG_RUN_ID=manual__2022-03-14T15:34:16.519518+00:00
[2022-03-14 15:34:29,331] {taskinstance.py:1718} ERROR - Task failed with exception
Traceback (most recent call last):
  File "/home/airflow/.local/lib/python3.7/site-packages/airflow/models/taskinstance.py", line 1334, in _run_raw_task
    self._execute_task_with_callbacks(context)
  File "/home/airflow/.local/lib/python3.7/site-packages/airflow/models/taskinstance.py", line 1460, in _execute_task_with_callbacks
    result = self._execute_task(context, self.task)
  File "/home/airflow/.local/lib/python3.7/site-packages/airflow/models/taskinstance.py", line 1516, in _execute_task
    result = execute_callable(context=context)
  File "/home/airflow/.local/lib/python3.7/site-packages/airflow/providers/postgres/operators/postgres.py", line 71, in execute
    self.hook.run(self.sql, self.autocommit, parameters=self.parameters)
  File "/home/airflow/.local/lib/python3.7/site-packages/airflow/hooks/dbapi.py", line 198, in run
    with closing(self.get_conn()) as conn:
  File "/home/airflow/.local/lib/python3.7/site-packages/airflow/providers/postgres/hooks/postgres.py", line 86, in get_conn
    conn = deepcopy(self.connection or self.get_connection(conn_id))
  File "/home/airflow/.local/lib/python3.7/site-packages/airflow/hooks/base.py", line 68, in get_connection
    conn = Connection.get_connection_from_secrets(conn_id)
  File "/home/airflow/.local/lib/python3.7/site-packages/airflow/models/connection.py", line 410, in get_connection_from_secrets
    raise AirflowNotFoundException(f"The conn_id `{conn_id}` isn't defined")
airflow.exceptions.AirflowNotFoundException: The conn_id `postgres_default` isn't defined
[2022-03-14 15:34:29,372] {taskinstance.py:1282} INFO - Marking task as UP_FOR_RETRY. dag_id=main_dag, task_id=create_weather_table, execution_date=20220314T153416, start_date=20220314T153428, end_date=20220314T153429
[2022-03-14 15:34:29,429] {standard_task_runner.py:92} ERROR - Failed to execute job 7 for task create_weather_table
Traceback (most recent call last):
  File "/home/airflow/.local/lib/python3.7/site-packages/airflow/task/task_runner/standard_task_runner.py", line 85, in _start_by_fork
    args.func(args, dag=self.dag)
  File "/home/airflow/.local/lib/python3.7/site-packages/airflow/cli/cli_parser.py", line 48, in command
    return func(*args, **kwargs)
  File "/home/airflow/.local/lib/python3.7/site-packages/airflow/utils/cli.py", line 92, in wrapper
    return f(*args, **kwargs)
  File "/home/airflow/.local/lib/python3.7/site-packages/airflow/cli/commands/task_command.py", line 298, in task_run
    _run_task_by_selected_method(args, dag, ti)
  File "/home/airflow/.local/lib/python3.7/site-packages/airflow/cli/commands/task_command.py", line 107, in _run_task_by_selected_method
    _run_raw_task(args, ti)
  File "/home/airflow/.local/lib/python3.7/site-packages/airflow/cli/commands/task_command.py", line 184, in _run_raw_task
    error_file=args.error_file,
  File "/home/airflow/.local/lib/python3.7/site-packages/airflow/utils/session.py", line 70, in wrapper
    return func(*args, session=session, **kwargs)
  File "/home/airflow/.local/lib/python3.7/site-packages/airflow/models/taskinstance.py", line 1334, in _run_raw_task
    self._execute_task_with_callbacks(context)
  File "/home/airflow/.local/lib/python3.7/site-packages/airflow/models/taskinstance.py", line 1460, in _execute_task_with_callbacks
    result = self._execute_task(context, self.task)
  File "/home/airflow/.local/lib/python3.7/site-packages/airflow/models/taskinstance.py", line 1516, in _execute_task
    result = execute_callable(context=context)
  File "/home/airflow/.local/lib/python3.7/site-packages/airflow/providers/postgres/operators/postgres.py", line 71, in execute
    self.hook.run(self.sql, self.autocommit, parameters=self.parameters)
  File "/home/airflow/.local/lib/python3.7/site-packages/airflow/hooks/dbapi.py", line 198, in run
    with closing(self.get_conn()) as conn:
  File "/home/airflow/.local/lib/python3.7/site-packages/airflow/providers/postgres/hooks/postgres.py", line 86, in get_conn
    conn = deepcopy(self.connection or self.get_connection(conn_id))
  File "/home/airflow/.local/lib/python3.7/site-packages/airflow/hooks/base.py", line 68, in get_connection
    conn = Connection.get_connection_from_secrets(conn_id)
  File "/home/airflow/.local/lib/python3.7/site-packages/airflow/models/connection.py", line 410, in get_connection_from_secrets
    raise AirflowNotFoundException(f"The conn_id `{conn_id}` isn't defined")
airflow.exceptions.AirflowNotFoundException: The conn_id `postgres_default` isn't defined
[2022-03-14 15:34:29,451] {local_task_job.py:154} INFO - Task exited with return code 1
[2022-03-14 15:34:29,564] {local_task_job.py:264} INFO - 0 downstream tasks scheduled from follow-on schedule check
