[2022-03-14 12:48:13,540] {taskinstance.py:1037} INFO - Dependencies all met for <TaskInstance: main_dag.fetch_weather_data scheduled__2022-03-13T00:00:00+00:00 [queued]>
[2022-03-14 12:48:13,631] {taskinstance.py:1037} INFO - Dependencies all met for <TaskInstance: main_dag.fetch_weather_data scheduled__2022-03-13T00:00:00+00:00 [queued]>
[2022-03-14 12:48:13,634] {taskinstance.py:1243} INFO - 
--------------------------------------------------------------------------------
[2022-03-14 12:48:13,639] {taskinstance.py:1244} INFO - Starting attempt 1 of 2
[2022-03-14 12:48:13,642] {taskinstance.py:1245} INFO - 
--------------------------------------------------------------------------------
[2022-03-14 12:48:13,744] {taskinstance.py:1264} INFO - Executing <Task(PythonOperator): fetch_weather_data> on 2022-03-13 00:00:00+00:00
[2022-03-14 12:48:13,760] {standard_task_runner.py:52} INFO - Started process 2512 to run task
[2022-03-14 12:48:13,773] {standard_task_runner.py:76} INFO - Running: ['***', 'tasks', 'run', 'main_dag', 'fetch_weather_data', 'scheduled__2022-03-13T00:00:00+00:00', '--job-id', '5', '--raw', '--subdir', 'DAGS_FOLDER/main_dag.py', '--cfg-path', '/tmp/tmpac_jg4_8', '--error-file', '/tmp/tmpcz57ozrj']
[2022-03-14 12:48:13,778] {standard_task_runner.py:77} INFO - Job 5: Subtask fetch_weather_data
[2022-03-14 12:48:14,131] {logging_mixin.py:109} INFO - Running <TaskInstance: main_dag.fetch_weather_data scheduled__2022-03-13T00:00:00+00:00 [running]> on host e0810cf0708b
[2022-03-14 12:48:14,731] {taskinstance.py:1431} INFO - Exporting the following env vars:
AIRFLOW_CTX_DAG_OWNER=***
AIRFLOW_CTX_DAG_ID=main_dag
AIRFLOW_CTX_TASK_ID=fetch_weather_data
AIRFLOW_CTX_EXECUTION_DATE=2022-03-13T00:00:00+00:00
AIRFLOW_CTX_DAG_RUN_ID=scheduled__2022-03-13T00:00:00+00:00
[2022-03-14 12:48:23,029] {python.py:175} INFO - Done. Returned value was: None
[2022-03-14 12:48:23,072] {taskinstance.py:1282} INFO - Marking task as SUCCESS. dag_id=main_dag, task_id=fetch_weather_data, execution_date=20220313T000000, start_date=20220314T124813, end_date=20220314T124823
[2022-03-14 12:48:23,148] {local_task_job.py:154} INFO - Task exited with return code 0
[2022-03-14 12:48:23,267] {local_task_job.py:264} INFO - 0 downstream tasks scheduled from follow-on schedule check
[2022-03-14 15:28:26,141] {taskinstance.py:1037} INFO - Dependencies all met for <TaskInstance: main_dag.fetch_weather_data scheduled__2022-03-13T00:00:00+00:00 [queued]>
[2022-03-14 15:28:26,181] {taskinstance.py:1037} INFO - Dependencies all met for <TaskInstance: main_dag.fetch_weather_data scheduled__2022-03-13T00:00:00+00:00 [queued]>
[2022-03-14 15:28:26,182] {taskinstance.py:1243} INFO - 
--------------------------------------------------------------------------------
[2022-03-14 15:28:26,184] {taskinstance.py:1244} INFO - Starting attempt 1 of 2
[2022-03-14 15:28:26,186] {taskinstance.py:1245} INFO - 
--------------------------------------------------------------------------------
[2022-03-14 15:28:26,225] {taskinstance.py:1264} INFO - Executing <Task(PythonOperator): fetch_weather_data> on 2022-03-13 00:00:00+00:00
[2022-03-14 15:28:26,233] {standard_task_runner.py:52} INFO - Started process 2228 to run task
[2022-03-14 15:28:26,240] {standard_task_runner.py:76} INFO - Running: ['***', 'tasks', 'run', 'main_dag', 'fetch_weather_data', 'scheduled__2022-03-13T00:00:00+00:00', '--job-id', '2', '--raw', '--subdir', 'DAGS_FOLDER/main_dag.py', '--cfg-path', '/tmp/tmpl1tqijrz', '--error-file', '/tmp/tmpkmzj8d7b']
[2022-03-14 15:28:26,243] {standard_task_runner.py:77} INFO - Job 2: Subtask fetch_weather_data
[2022-03-14 15:28:26,362] {logging_mixin.py:109} INFO - Running <TaskInstance: main_dag.fetch_weather_data scheduled__2022-03-13T00:00:00+00:00 [running]> on host 0bb54ecb374d
[2022-03-14 15:28:26,506] {taskinstance.py:1431} INFO - Exporting the following env vars:
AIRFLOW_CTX_DAG_OWNER=***
AIRFLOW_CTX_DAG_ID=main_dag
AIRFLOW_CTX_TASK_ID=fetch_weather_data
AIRFLOW_CTX_EXECUTION_DATE=2022-03-13T00:00:00+00:00
AIRFLOW_CTX_DAG_RUN_ID=scheduled__2022-03-13T00:00:00+00:00
[2022-03-14 15:28:33,317] {logging_mixin.py:109} INFO - 2
[2022-03-14 15:28:33,320] {get_current_weather_data.py:46} ERROR - Request for West Bengal unsuccessful with status code: 429
[2022-03-14 15:28:33,322] {get_current_weather_data.py:47} INFO - JSON Response:
{"message":"You have exceeded the rate limit per minute for your plan, BASIC, by the API provider"}
[2022-03-14 15:28:33,355] {taskinstance.py:1718} ERROR - Task failed with exception
Traceback (most recent call last):
  File "/opt/airflow/dags/python_scripts/get_current_weather_data.py", line 43, in get_current_weather_data
    raise Exception
Exception

During handling of the above exception, another exception occurred:

Traceback (most recent call last):
  File "/home/airflow/.local/lib/python3.7/site-packages/airflow/models/taskinstance.py", line 1334, in _run_raw_task
    self._execute_task_with_callbacks(context)
  File "/home/airflow/.local/lib/python3.7/site-packages/airflow/models/taskinstance.py", line 1460, in _execute_task_with_callbacks
    result = self._execute_task(context, self.task)
  File "/home/airflow/.local/lib/python3.7/site-packages/airflow/models/taskinstance.py", line 1516, in _execute_task
    result = execute_callable(context=context)
  File "/home/airflow/.local/lib/python3.7/site-packages/airflow/operators/python.py", line 174, in execute
    return_value = self.execute_callable()
  File "/home/airflow/.local/lib/python3.7/site-packages/airflow/operators/python.py", line 188, in execute_callable
    return self.python_callable(*self.op_args, **self.op_kwargs)
  File "/opt/airflow/dags/python_scripts/get_current_weather_data.py", line 48, in get_current_weather_data
    raise AirflowException
airflow.exceptions.AirflowException
[2022-03-14 15:28:33,388] {taskinstance.py:1282} INFO - Marking task as UP_FOR_RETRY. dag_id=main_dag, task_id=fetch_weather_data, execution_date=20220313T000000, start_date=20220314T152826, end_date=20220314T152833
[2022-03-14 15:28:33,435] {standard_task_runner.py:92} ERROR - Failed to execute job 2 for task fetch_weather_data
Traceback (most recent call last):
  File "/opt/airflow/dags/python_scripts/get_current_weather_data.py", line 43, in get_current_weather_data
    raise Exception
Exception

During handling of the above exception, another exception occurred:

Traceback (most recent call last):
  File "/home/airflow/.local/lib/python3.7/site-packages/airflow/task/task_runner/standard_task_runner.py", line 85, in _start_by_fork
    args.func(args, dag=self.dag)
  File "/home/airflow/.local/lib/python3.7/site-packages/airflow/cli/cli_parser.py", line 48, in command
    return func(*args, **kwargs)
  File "/home/airflow/.local/lib/python3.7/site-packages/airflow/utils/cli.py", line 92, in wrapper
    return f(*args, **kwargs)
  File "/home/airflow/.local/lib/python3.7/site-packages/airflow/cli/commands/task_command.py", line 298, in task_run
    _run_task_by_selected_method(args, dag, ti)
  File "/home/airflow/.local/lib/python3.7/site-packages/airflow/cli/commands/task_command.py", line 107, in _run_task_by_selected_method
    _run_raw_task(args, ti)
  File "/home/airflow/.local/lib/python3.7/site-packages/airflow/cli/commands/task_command.py", line 184, in _run_raw_task
    error_file=args.error_file,
  File "/home/airflow/.local/lib/python3.7/site-packages/airflow/utils/session.py", line 70, in wrapper
    return func(*args, session=session, **kwargs)
  File "/home/airflow/.local/lib/python3.7/site-packages/airflow/models/taskinstance.py", line 1334, in _run_raw_task
    self._execute_task_with_callbacks(context)
  File "/home/airflow/.local/lib/python3.7/site-packages/airflow/models/taskinstance.py", line 1460, in _execute_task_with_callbacks
    result = self._execute_task(context, self.task)
  File "/home/airflow/.local/lib/python3.7/site-packages/airflow/models/taskinstance.py", line 1516, in _execute_task
    result = execute_callable(context=context)
  File "/home/airflow/.local/lib/python3.7/site-packages/airflow/operators/python.py", line 174, in execute
    return_value = self.execute_callable()
  File "/home/airflow/.local/lib/python3.7/site-packages/airflow/operators/python.py", line 188, in execute_callable
    return self.python_callable(*self.op_args, **self.op_kwargs)
  File "/opt/airflow/dags/python_scripts/get_current_weather_data.py", line 48, in get_current_weather_data
    raise AirflowException
airflow.exceptions.AirflowException
[2022-03-14 15:28:33,482] {local_task_job.py:154} INFO - Task exited with return code 1
[2022-03-14 15:28:33,758] {local_task_job.py:264} INFO - 0 downstream tasks scheduled from follow-on schedule check
