[2022-03-14 13:16:41,559] {taskinstance.py:1037} INFO - Dependencies all met for <TaskInstance: main_dag.populate_weather_table manual__2022-03-14T13:16:05.400700+00:00 [queued]>
[2022-03-14 13:16:41,626] {taskinstance.py:1037} INFO - Dependencies all met for <TaskInstance: main_dag.populate_weather_table manual__2022-03-14T13:16:05.400700+00:00 [queued]>
[2022-03-14 13:16:41,628] {taskinstance.py:1243} INFO - 
--------------------------------------------------------------------------------
[2022-03-14 13:16:41,632] {taskinstance.py:1244} INFO - Starting attempt 2 of 2
[2022-03-14 13:16:41,636] {taskinstance.py:1245} INFO - 
--------------------------------------------------------------------------------
[2022-03-14 13:16:41,726] {taskinstance.py:1264} INFO - Executing <Task(PostgresOperator): populate_weather_table> on 2022-03-14 13:16:05.400700+00:00
[2022-03-14 13:16:41,744] {standard_task_runner.py:52} INFO - Started process 759 to run task
[2022-03-14 13:16:41,761] {standard_task_runner.py:76} INFO - Running: ['***', 'tasks', 'run', 'main_dag', 'populate_weather_table', 'manual__2022-03-14T13:16:05.400700+00:00', '--job-id', '12', '--raw', '--subdir', 'DAGS_FOLDER/main_dag.py', '--cfg-path', '/tmp/tmpa5pubn7i', '--error-file', '/tmp/tmp2r6q96w7']
[2022-03-14 13:16:41,769] {standard_task_runner.py:77} INFO - Job 12: Subtask populate_weather_table
[2022-03-14 13:16:41,947] {logging_mixin.py:109} INFO - Running <TaskInstance: main_dag.populate_weather_table manual__2022-03-14T13:16:05.400700+00:00 [running]> on host e0810cf0708b
[2022-03-14 13:16:42,113] {taskinstance.py:1431} INFO - Exporting the following env vars:
AIRFLOW_CTX_DAG_OWNER=***
AIRFLOW_CTX_DAG_ID=main_dag
AIRFLOW_CTX_TASK_ID=populate_weather_table
AIRFLOW_CTX_EXECUTION_DATE=2022-03-14T13:16:05.400700+00:00
AIRFLOW_CTX_DAG_RUN_ID=manual__2022-03-14T13:16:05.400700+00:00
[2022-03-14 13:16:42,139] {taskinstance.py:1718} ERROR - Task failed with exception
Traceback (most recent call last):
  File "/home/airflow/.local/lib/python3.7/site-packages/airflow/models/taskinstance.py", line 1334, in _run_raw_task
    self._execute_task_with_callbacks(context)
  File "/home/airflow/.local/lib/python3.7/site-packages/airflow/models/taskinstance.py", line 1460, in _execute_task_with_callbacks
    result = self._execute_task(context, self.task)
  File "/home/airflow/.local/lib/python3.7/site-packages/airflow/models/taskinstance.py", line 1516, in _execute_task
    result = execute_callable(context=context)
  File "/home/airflow/.local/lib/python3.7/site-packages/airflow/providers/postgres/operators/postgres.py", line 71, in execute
    self.hook.run(self.sql, self.autocommit, parameters=self.parameters)
  File "/home/airflow/.local/lib/python3.7/site-packages/airflow/hooks/dbapi.py", line 198, in run
    with closing(self.get_conn()) as conn:
  File "/home/airflow/.local/lib/python3.7/site-packages/airflow/providers/postgres/hooks/postgres.py", line 113, in get_conn
    self.conn = psycopg2.connect(**conn_args)
  File "/home/airflow/.local/lib/python3.7/site-packages/psycopg2/__init__.py", line 122, in connect
    conn = _connect(dsn, connection_factory=connection_factory, **kwasync)
psycopg2.OperationalError: connection to server on socket "/var/run/postgresql/.s.PGSQL.5432" failed: No such file or directory
	Is the server running locally and accepting connections on that socket?

[2022-03-14 13:16:42,181] {taskinstance.py:1282} INFO - Marking task as FAILED. dag_id=main_dag, task_id=populate_weather_table, execution_date=20220314T131605, start_date=20220314T131641, end_date=20220314T131642
[2022-03-14 13:16:42,229] {standard_task_runner.py:92} ERROR - Failed to execute job 12 for task populate_weather_table
Traceback (most recent call last):
  File "/home/airflow/.local/lib/python3.7/site-packages/airflow/task/task_runner/standard_task_runner.py", line 85, in _start_by_fork
    args.func(args, dag=self.dag)
  File "/home/airflow/.local/lib/python3.7/site-packages/airflow/cli/cli_parser.py", line 48, in command
    return func(*args, **kwargs)
  File "/home/airflow/.local/lib/python3.7/site-packages/airflow/utils/cli.py", line 92, in wrapper
    return f(*args, **kwargs)
  File "/home/airflow/.local/lib/python3.7/site-packages/airflow/cli/commands/task_command.py", line 298, in task_run
    _run_task_by_selected_method(args, dag, ti)
  File "/home/airflow/.local/lib/python3.7/site-packages/airflow/cli/commands/task_command.py", line 107, in _run_task_by_selected_method
    _run_raw_task(args, ti)
  File "/home/airflow/.local/lib/python3.7/site-packages/airflow/cli/commands/task_command.py", line 184, in _run_raw_task
    error_file=args.error_file,
  File "/home/airflow/.local/lib/python3.7/site-packages/airflow/utils/session.py", line 70, in wrapper
    return func(*args, session=session, **kwargs)
  File "/home/airflow/.local/lib/python3.7/site-packages/airflow/models/taskinstance.py", line 1334, in _run_raw_task
    self._execute_task_with_callbacks(context)
  File "/home/airflow/.local/lib/python3.7/site-packages/airflow/models/taskinstance.py", line 1460, in _execute_task_with_callbacks
    result = self._execute_task(context, self.task)
  File "/home/airflow/.local/lib/python3.7/site-packages/airflow/models/taskinstance.py", line 1516, in _execute_task
    result = execute_callable(context=context)
  File "/home/airflow/.local/lib/python3.7/site-packages/airflow/providers/postgres/operators/postgres.py", line 71, in execute
    self.hook.run(self.sql, self.autocommit, parameters=self.parameters)
  File "/home/airflow/.local/lib/python3.7/site-packages/airflow/hooks/dbapi.py", line 198, in run
    with closing(self.get_conn()) as conn:
  File "/home/airflow/.local/lib/python3.7/site-packages/airflow/providers/postgres/hooks/postgres.py", line 113, in get_conn
    self.conn = psycopg2.connect(**conn_args)
  File "/home/airflow/.local/lib/python3.7/site-packages/psycopg2/__init__.py", line 122, in connect
    conn = _connect(dsn, connection_factory=connection_factory, **kwasync)
psycopg2.OperationalError: connection to server on socket "/var/run/postgresql/.s.PGSQL.5432" failed: No such file or directory
	Is the server running locally and accepting connections on that socket?

[2022-03-14 13:16:42,253] {local_task_job.py:154} INFO - Task exited with return code 1
[2022-03-14 13:16:42,361] {local_task_job.py:264} INFO - 0 downstream tasks scheduled from follow-on schedule check
