[2022-03-14 14:05:29,787] {taskinstance.py:1037} INFO - Dependencies all met for <TaskInstance: main_dag.fetch_weather_data manual__2022-03-14T14:05:26.868640+00:00 [queued]>
[2022-03-14 14:05:29,829] {taskinstance.py:1037} INFO - Dependencies all met for <TaskInstance: main_dag.fetch_weather_data manual__2022-03-14T14:05:26.868640+00:00 [queued]>
[2022-03-14 14:05:29,831] {taskinstance.py:1243} INFO - 
--------------------------------------------------------------------------------
[2022-03-14 14:05:29,834] {taskinstance.py:1244} INFO - Starting attempt 1 of 2
[2022-03-14 14:05:29,835] {taskinstance.py:1245} INFO - 
--------------------------------------------------------------------------------
[2022-03-14 14:05:29,880] {taskinstance.py:1264} INFO - Executing <Task(PythonOperator): fetch_weather_data> on 2022-03-14 14:05:26.868640+00:00
[2022-03-14 14:05:29,888] {standard_task_runner.py:52} INFO - Started process 2981 to run task
[2022-03-14 14:05:29,895] {standard_task_runner.py:76} INFO - Running: ['***', 'tasks', 'run', 'main_dag', 'fetch_weather_data', 'manual__2022-03-14T14:05:26.868640+00:00', '--job-id', '19', '--raw', '--subdir', 'DAGS_FOLDER/main_dag.py', '--cfg-path', '/tmp/tmp9uf1wl89', '--error-file', '/tmp/tmpg5rpv073']
[2022-03-14 14:05:29,898] {standard_task_runner.py:77} INFO - Job 19: Subtask fetch_weather_data
[2022-03-14 14:05:30,052] {logging_mixin.py:109} INFO - Running <TaskInstance: main_dag.fetch_weather_data manual__2022-03-14T14:05:26.868640+00:00 [running]> on host e0810cf0708b
[2022-03-14 14:05:30,420] {taskinstance.py:1431} INFO - Exporting the following env vars:
AIRFLOW_CTX_DAG_OWNER=***
AIRFLOW_CTX_DAG_ID=main_dag
AIRFLOW_CTX_TASK_ID=fetch_weather_data
AIRFLOW_CTX_EXECUTION_DATE=2022-03-14T14:05:26.868640+00:00
AIRFLOW_CTX_DAG_RUN_ID=manual__2022-03-14T14:05:26.868640+00:00
[2022-03-14 14:05:31,895] {taskinstance.py:1718} ERROR - Task failed with exception
Traceback (most recent call last):
  File "/home/airflow/.local/lib/python3.7/site-packages/requests/utils.py", line 1024, in check_header_validity
    if not pat.match(value):
TypeError: expected string or bytes-like object

During handling of the above exception, another exception occurred:

Traceback (most recent call last):
  File "/opt/airflow/dags/python_scripts/get_current_weather_data.py", line 21, in get_current_weather_data
    response = requests.request("GET", url, headers=headers, params={"q":state})
  File "/home/airflow/.local/lib/python3.7/site-packages/requests/api.py", line 61, in request
    return session.request(method=method, url=url, **kwargs)
  File "/home/airflow/.local/lib/python3.7/site-packages/requests/sessions.py", line 515, in request
    prep = self.prepare_request(req)
  File "/home/airflow/.local/lib/python3.7/site-packages/requests/sessions.py", line 453, in prepare_request
    hooks=merge_hooks(request.hooks, self.hooks),
  File "/home/airflow/.local/lib/python3.7/site-packages/requests/models.py", line 319, in prepare
    self.prepare_headers(headers)
  File "/home/airflow/.local/lib/python3.7/site-packages/requests/models.py", line 453, in prepare_headers
    check_header_validity(header)
  File "/home/airflow/.local/lib/python3.7/site-packages/requests/utils.py", line 1028, in check_header_validity
    "bytes, not %s" % (name, value, type(value)))
requests.exceptions.InvalidHeader: Value for header {x-rapidapi-key: <function get_rapidapi_key at 0x401fa8d680>} must be of type str or bytes, not <class 'function'>

During handling of the above exception, another exception occurred:

Traceback (most recent call last):
  File "/home/airflow/.local/lib/python3.7/site-packages/airflow/models/taskinstance.py", line 1334, in _run_raw_task
    self._execute_task_with_callbacks(context)
  File "/home/airflow/.local/lib/python3.7/site-packages/airflow/models/taskinstance.py", line 1460, in _execute_task_with_callbacks
    result = self._execute_task(context, self.task)
  File "/home/airflow/.local/lib/python3.7/site-packages/airflow/models/taskinstance.py", line 1516, in _execute_task
    result = execute_callable(context=context)
  File "/home/airflow/.local/lib/python3.7/site-packages/airflow/operators/python.py", line 174, in execute
    return_value = self.execute_callable()
  File "/home/airflow/.local/lib/python3.7/site-packages/airflow/operators/python.py", line 188, in execute_callable
    return self.python_callable(*self.op_args, **self.op_kwargs)
  File "/opt/airflow/dags/python_scripts/get_current_weather_data.py", line 45, in get_current_weather_data
    logging.error(f"Request for {state} unsuccessful with status code: {response.status_code}")
UnboundLocalError: local variable 'response' referenced before assignment
[2022-03-14 14:05:31,941] {taskinstance.py:1282} INFO - Marking task as UP_FOR_RETRY. dag_id=main_dag, task_id=fetch_weather_data, execution_date=20220314T140526, start_date=20220314T140529, end_date=20220314T140531
[2022-03-14 14:05:32,065] {standard_task_runner.py:92} ERROR - Failed to execute job 19 for task fetch_weather_data
Traceback (most recent call last):
  File "/home/airflow/.local/lib/python3.7/site-packages/requests/utils.py", line 1024, in check_header_validity
    if not pat.match(value):
TypeError: expected string or bytes-like object

During handling of the above exception, another exception occurred:

Traceback (most recent call last):
  File "/opt/airflow/dags/python_scripts/get_current_weather_data.py", line 21, in get_current_weather_data
    response = requests.request("GET", url, headers=headers, params={"q":state})
  File "/home/airflow/.local/lib/python3.7/site-packages/requests/api.py", line 61, in request
    return session.request(method=method, url=url, **kwargs)
  File "/home/airflow/.local/lib/python3.7/site-packages/requests/sessions.py", line 515, in request
    prep = self.prepare_request(req)
  File "/home/airflow/.local/lib/python3.7/site-packages/requests/sessions.py", line 453, in prepare_request
    hooks=merge_hooks(request.hooks, self.hooks),
  File "/home/airflow/.local/lib/python3.7/site-packages/requests/models.py", line 319, in prepare
    self.prepare_headers(headers)
  File "/home/airflow/.local/lib/python3.7/site-packages/requests/models.py", line 453, in prepare_headers
    check_header_validity(header)
  File "/home/airflow/.local/lib/python3.7/site-packages/requests/utils.py", line 1028, in check_header_validity
    "bytes, not %s" % (name, value, type(value)))
requests.exceptions.InvalidHeader: Value for header {x-rapidapi-key: <function get_rapidapi_key at 0x401fa8d680>} must be of type str or bytes, not <class 'function'>

During handling of the above exception, another exception occurred:

Traceback (most recent call last):
  File "/home/airflow/.local/lib/python3.7/site-packages/airflow/task/task_runner/standard_task_runner.py", line 85, in _start_by_fork
    args.func(args, dag=self.dag)
  File "/home/airflow/.local/lib/python3.7/site-packages/airflow/cli/cli_parser.py", line 48, in command
    return func(*args, **kwargs)
  File "/home/airflow/.local/lib/python3.7/site-packages/airflow/utils/cli.py", line 92, in wrapper
    return f(*args, **kwargs)
  File "/home/airflow/.local/lib/python3.7/site-packages/airflow/cli/commands/task_command.py", line 298, in task_run
    _run_task_by_selected_method(args, dag, ti)
  File "/home/airflow/.local/lib/python3.7/site-packages/airflow/cli/commands/task_command.py", line 107, in _run_task_by_selected_method
    _run_raw_task(args, ti)
  File "/home/airflow/.local/lib/python3.7/site-packages/airflow/cli/commands/task_command.py", line 184, in _run_raw_task
    error_file=args.error_file,
  File "/home/airflow/.local/lib/python3.7/site-packages/airflow/utils/session.py", line 70, in wrapper
    return func(*args, session=session, **kwargs)
  File "/home/airflow/.local/lib/python3.7/site-packages/airflow/models/taskinstance.py", line 1334, in _run_raw_task
    self._execute_task_with_callbacks(context)
  File "/home/airflow/.local/lib/python3.7/site-packages/airflow/models/taskinstance.py", line 1460, in _execute_task_with_callbacks
    result = self._execute_task(context, self.task)
  File "/home/airflow/.local/lib/python3.7/site-packages/airflow/models/taskinstance.py", line 1516, in _execute_task
    result = execute_callable(context=context)
  File "/home/airflow/.local/lib/python3.7/site-packages/airflow/operators/python.py", line 174, in execute
    return_value = self.execute_callable()
  File "/home/airflow/.local/lib/python3.7/site-packages/airflow/operators/python.py", line 188, in execute_callable
    return self.python_callable(*self.op_args, **self.op_kwargs)
  File "/opt/airflow/dags/python_scripts/get_current_weather_data.py", line 45, in get_current_weather_data
    logging.error(f"Request for {state} unsuccessful with status code: {response.status_code}")
UnboundLocalError: local variable 'response' referenced before assignment
[2022-03-14 14:05:32,092] {local_task_job.py:154} INFO - Task exited with return code 1
[2022-03-14 14:05:32,199] {local_task_job.py:264} INFO - 0 downstream tasks scheduled from follow-on schedule check
